[2024-11-10T23:28:35.568+0000] {local_task_job_runner.py:120} INFO - ::group::Pre task execution logs
[2024-11-10T23:28:35.887+0000] {taskinstance.py:2076} INFO - Dependencies all met for dep_context=non-requeueable deps ti=<TaskInstance: dbt_airflow_dag.dbt_run manual__2024-11-10T23:23:31.522268+00:00 [queued]>
[2024-11-10T23:28:36.036+0000] {taskinstance.py:2076} INFO - Dependencies all met for dep_context=requeueable deps ti=<TaskInstance: dbt_airflow_dag.dbt_run manual__2024-11-10T23:23:31.522268+00:00 [queued]>
[2024-11-10T23:28:36.043+0000] {taskinstance.py:2306} INFO - Starting attempt 2 of 2
[2024-11-10T23:28:36.095+0000] {taskinstance.py:2330} INFO - Executing <Task(BashOperator): dbt_run> on 2024-11-10 23:23:31.522268+00:00
[2024-11-10T23:28:36.158+0000] {warnings.py:110} WARNING - /home/***/.local/lib/python3.12/site-packages/***/task/task_runner/standard_task_runner.py:61: DeprecationWarning: This process (pid=2577) is multi-threaded, use of fork() may lead to deadlocks in the child.
  pid = os.fork()

[2024-11-10T23:28:36.201+0000] {standard_task_runner.py:63} INFO - Started process 2579 to run task
[2024-11-10T23:28:36.177+0000] {standard_task_runner.py:90} INFO - Running: ['***', 'tasks', 'run', 'dbt_***_dag', 'dbt_run', 'manual__2024-11-10T23:23:31.522268+00:00', '--job-id', '163', '--raw', '--subdir', 'DAGS_FOLDER/ELT_Macd_calculation.py', '--cfg-path', '/tmp/tmplqbybvpc']
[2024-11-10T23:28:36.208+0000] {standard_task_runner.py:91} INFO - Job 163: Subtask dbt_run
[2024-11-10T23:28:36.814+0000] {task_command.py:426} INFO - Running <TaskInstance: dbt_airflow_dag.dbt_run manual__2024-11-10T23:23:31.522268+00:00 [running]> on host 64c676815d01
[2024-11-10T23:28:37.247+0000] {taskinstance.py:2648} INFO - Exporting env vars: AIRFLOW_CTX_DAG_OWNER='***' AIRFLOW_CTX_DAG_ID='dbt_***_dag' AIRFLOW_CTX_TASK_ID='dbt_run' AIRFLOW_CTX_EXECUTION_DATE='2024-11-10T23:23:31.522268+00:00' AIRFLOW_CTX_TRY_NUMBER='2' AIRFLOW_CTX_DAG_RUN_ID='manual__2024-11-10T23:23:31.522268+00:00'
[2024-11-10T23:28:37.282+0000] {taskinstance.py:430} INFO - ::endgroup::
[2024-11-10T23:28:37.321+0000] {subprocess.py:63} INFO - Tmp dir root location: /tmp
[2024-11-10T23:28:37.329+0000] {subprocess.py:75} INFO - Running command: ['/usr/bin/bash', '-c', 'cd /Documents/***/sjsu-data226/build_lab2 && dbt run']
[2024-11-10T23:28:37.384+0000] {subprocess.py:86} INFO - Output:
[2024-11-10T23:28:37.455+0000] {subprocess.py:93} INFO - /usr/bin/bash: line 1: cd: /Documents/***/sjsu-data226/build_lab2: No such file or directory
[2024-11-10T23:28:37.461+0000] {subprocess.py:97} INFO - Command exited with return code 1
[2024-11-10T23:28:37.464+0000] {taskinstance.py:441} INFO - ::group::Post task execution logs
[2024-11-10T23:28:37.590+0000] {taskinstance.py:2905} ERROR - Task failed with exception
Traceback (most recent call last):
  File "/home/airflow/.local/lib/python3.12/site-packages/airflow/models/taskinstance.py", line 465, in _execute_task
    result = _execute_callable(context=context, **execute_callable_kwargs)
             ^^^^^^^^^^^^^^^^^^^^^^^^^^^^^^^^^^^^^^^^^^^^^^^^^^^^^^^^^^^^^
  File "/home/airflow/.local/lib/python3.12/site-packages/airflow/models/taskinstance.py", line 432, in _execute_callable
    return execute_callable(context=context, **execute_callable_kwargs)
           ^^^^^^^^^^^^^^^^^^^^^^^^^^^^^^^^^^^^^^^^^^^^^^^^^^^^^^^^^^^^
  File "/home/airflow/.local/lib/python3.12/site-packages/airflow/models/baseoperator.py", line 400, in wrapper
    return func(self, *args, **kwargs)
           ^^^^^^^^^^^^^^^^^^^^^^^^^^^
  File "/home/airflow/.local/lib/python3.12/site-packages/airflow/operators/bash.py", line 243, in execute
    raise AirflowException(
airflow.exceptions.AirflowException: Bash command failed. The command returned a non-zero exit code 1.
[2024-11-10T23:28:37.851+0000] {taskinstance.py:1206} INFO - Marking task as FAILED. dag_id=dbt_***_dag, task_id=dbt_run, run_id=manual__2024-11-10T23:23:31.522268+00:00, execution_date=20241110T232331, start_date=20241110T232835, end_date=20241110T232837
[2024-11-10T23:28:45.634+0000] {standard_task_runner.py:110} ERROR - Failed to execute job 163 for task dbt_run (Bash command failed. The command returned a non-zero exit code 1.; 2579)
[2024-11-10T23:28:45.884+0000] {local_task_job_runner.py:240} INFO - Task exited with return code 1
[2024-11-10T23:28:46.207+0000] {taskinstance.py:3498} INFO - 0 downstream tasks scheduled from follow-on schedule check
[2024-11-10T23:28:46.254+0000] {local_task_job_runner.py:222} INFO - ::endgroup::
