[2024-11-10T23:23:32.242+0000] {local_task_job_runner.py:120} INFO - ::group::Pre task execution logs
[2024-11-10T23:23:32.280+0000] {taskinstance.py:2076} INFO - Dependencies all met for dep_context=non-requeueable deps ti=<TaskInstance: dbt_airflow_dag.dbt_run manual__2024-11-10T23:23:31.522268+00:00 [queued]>
[2024-11-10T23:23:32.284+0000] {taskinstance.py:2076} INFO - Dependencies all met for dep_context=requeueable deps ti=<TaskInstance: dbt_airflow_dag.dbt_run manual__2024-11-10T23:23:31.522268+00:00 [queued]>
[2024-11-10T23:23:32.284+0000] {taskinstance.py:2306} INFO - Starting attempt 1 of 2
[2024-11-10T23:23:32.290+0000] {taskinstance.py:2330} INFO - Executing <Task(BashOperator): dbt_run> on 2024-11-10 23:23:31.522268+00:00
[2024-11-10T23:23:32.301+0000] {logging_mixin.py:188} WARNING - /home/***/.local/lib/python3.12/site-packages/***/task/task_runner/standard_task_runner.py:61 DeprecationWarning: This process (pid=3322) is multi-threaded, use of fork() may lead to deadlocks in the child.
[2024-11-10T23:23:32.300+0000] {standard_task_runner.py:90} INFO - Running: ['***', 'tasks', 'run', 'dbt_***_dag', 'dbt_run', 'manual__2024-11-10T23:23:31.522268+00:00', '--job-id', '162', '--raw', '--subdir', 'DAGS_FOLDER/ELT_Macd_calculation.py', '--cfg-path', '/tmp/tmptpx0_qf8']
[2024-11-10T23:23:32.304+0000] {standard_task_runner.py:91} INFO - Job 162: Subtask dbt_run
[2024-11-10T23:23:32.303+0000] {standard_task_runner.py:63} INFO - Started process 3323 to run task
[2024-11-10T23:23:32.340+0000] {task_command.py:426} INFO - Running <TaskInstance: dbt_airflow_dag.dbt_run manual__2024-11-10T23:23:31.522268+00:00 [running]> on host 599a8e9540bd
[2024-11-10T23:23:32.387+0000] {taskinstance.py:2648} INFO - Exporting env vars: AIRFLOW_CTX_DAG_OWNER='***' AIRFLOW_CTX_DAG_ID='dbt_***_dag' AIRFLOW_CTX_TASK_ID='dbt_run' AIRFLOW_CTX_EXECUTION_DATE='2024-11-10T23:23:31.522268+00:00' AIRFLOW_CTX_TRY_NUMBER='1' AIRFLOW_CTX_DAG_RUN_ID='manual__2024-11-10T23:23:31.522268+00:00'
[2024-11-10T23:23:32.387+0000] {taskinstance.py:430} INFO - ::endgroup::
[2024-11-10T23:23:32.404+0000] {subprocess.py:63} INFO - Tmp dir root location: /tmp
[2024-11-10T23:23:32.406+0000] {subprocess.py:75} INFO - Running command: ['/usr/bin/bash', '-c', 'cd /Documents/***/sjsu-data226/build_lab2 && dbt run']
[2024-11-10T23:23:32.414+0000] {subprocess.py:86} INFO - Output:
[2024-11-10T23:23:32.425+0000] {subprocess.py:93} INFO - /usr/bin/bash: line 1: cd: /Documents/***/sjsu-data226/build_lab2: No such file or directory
[2024-11-10T23:23:32.425+0000] {subprocess.py:97} INFO - Command exited with return code 1
[2024-11-10T23:23:32.425+0000] {taskinstance.py:441} INFO - ::group::Post task execution logs
[2024-11-10T23:23:32.432+0000] {taskinstance.py:2905} ERROR - Task failed with exception
Traceback (most recent call last):
  File "/home/airflow/.local/lib/python3.12/site-packages/airflow/models/taskinstance.py", line 465, in _execute_task
    result = _execute_callable(context=context, **execute_callable_kwargs)
             ^^^^^^^^^^^^^^^^^^^^^^^^^^^^^^^^^^^^^^^^^^^^^^^^^^^^^^^^^^^^^
  File "/home/airflow/.local/lib/python3.12/site-packages/airflow/models/taskinstance.py", line 432, in _execute_callable
    return execute_callable(context=context, **execute_callable_kwargs)
           ^^^^^^^^^^^^^^^^^^^^^^^^^^^^^^^^^^^^^^^^^^^^^^^^^^^^^^^^^^^^
  File "/home/airflow/.local/lib/python3.12/site-packages/airflow/models/baseoperator.py", line 400, in wrapper
    return func(self, *args, **kwargs)
           ^^^^^^^^^^^^^^^^^^^^^^^^^^^
  File "/home/airflow/.local/lib/python3.12/site-packages/airflow/operators/bash.py", line 243, in execute
    raise AirflowException(
airflow.exceptions.AirflowException: Bash command failed. The command returned a non-zero exit code 1.
[2024-11-10T23:23:32.435+0000] {taskinstance.py:1206} INFO - Marking task as UP_FOR_RETRY. dag_id=dbt_***_dag, task_id=dbt_run, run_id=manual__2024-11-10T23:23:31.522268+00:00, execution_date=20241110T232331, start_date=20241110T232332, end_date=20241110T232332
[2024-11-10T23:23:32.443+0000] {standard_task_runner.py:110} ERROR - Failed to execute job 162 for task dbt_run (Bash command failed. The command returned a non-zero exit code 1.; 3323)
[2024-11-10T23:23:32.488+0000] {local_task_job_runner.py:240} INFO - Task exited with return code 1
[2024-11-10T23:23:32.499+0000] {taskinstance.py:3498} INFO - 0 downstream tasks scheduled from follow-on schedule check
[2024-11-10T23:23:32.499+0000] {local_task_job_runner.py:222} INFO - ::endgroup::
