[2024-11-10T23:45:40.009+0000] {local_task_job_runner.py:120} INFO - ::group::Pre task execution logs
[2024-11-10T23:45:40.029+0000] {taskinstance.py:2076} INFO - Dependencies all met for dep_context=non-requeueable deps ti=<TaskInstance: dbt_airflow_dag.dbt_run manual__2024-11-10T23:45:37.775594+00:00 [queued]>
[2024-11-10T23:45:40.032+0000] {taskinstance.py:2076} INFO - Dependencies all met for dep_context=requeueable deps ti=<TaskInstance: dbt_airflow_dag.dbt_run manual__2024-11-10T23:45:37.775594+00:00 [queued]>
[2024-11-10T23:45:40.033+0000] {taskinstance.py:2306} INFO - Starting attempt 1 of 1
[2024-11-10T23:45:40.039+0000] {taskinstance.py:2330} INFO - Executing <Task(BashOperator): dbt_run> on 2024-11-10 23:45:37.775594+00:00
[2024-11-10T23:45:40.047+0000] {warnings.py:110} WARNING - /home/***/.local/lib/python3.12/site-packages/***/task/task_runner/standard_task_runner.py:61: DeprecationWarning: This process (pid=2805) is multi-threaded, use of fork() may lead to deadlocks in the child.
  pid = os.fork()

[2024-11-10T23:45:40.048+0000] {standard_task_runner.py:63} INFO - Started process 2807 to run task
[2024-11-10T23:45:40.048+0000] {standard_task_runner.py:90} INFO - Running: ['***', 'tasks', 'run', 'dbt_***_dag', 'dbt_run', 'manual__2024-11-10T23:45:37.775594+00:00', '--job-id', '167', '--raw', '--subdir', 'DAGS_FOLDER/ELT_Macd_calculation.py', '--cfg-path', '/tmp/tmp6lg_2ukw']
[2024-11-10T23:45:40.050+0000] {standard_task_runner.py:91} INFO - Job 167: Subtask dbt_run
[2024-11-10T23:45:40.082+0000] {task_command.py:426} INFO - Running <TaskInstance: dbt_airflow_dag.dbt_run manual__2024-11-10T23:45:37.775594+00:00 [running]> on host 64c676815d01
[2024-11-10T23:45:40.132+0000] {taskinstance.py:2648} INFO - Exporting env vars: AIRFLOW_CTX_DAG_OWNER='***' AIRFLOW_CTX_DAG_ID='dbt_***_dag' AIRFLOW_CTX_TASK_ID='dbt_run' AIRFLOW_CTX_EXECUTION_DATE='2024-11-10T23:45:37.775594+00:00' AIRFLOW_CTX_TRY_NUMBER='1' AIRFLOW_CTX_DAG_RUN_ID='manual__2024-11-10T23:45:37.775594+00:00'
[2024-11-10T23:45:40.133+0000] {taskinstance.py:430} INFO - ::endgroup::
[2024-11-10T23:45:40.135+0000] {subprocess.py:63} INFO - Tmp dir root location: /tmp
[2024-11-10T23:45:40.136+0000] {subprocess.py:75} INFO - Running command: ['/usr/bin/bash', '-c', 'cd "/Users/gayatripatil/Documents/***/sjsu-data226/build_lab2" && dbt run']
[2024-11-10T23:45:40.147+0000] {subprocess.py:86} INFO - Output:
[2024-11-10T23:45:40.159+0000] {subprocess.py:93} INFO - /usr/bin/bash: line 1: cd: /Users/gayatripatil/Documents/***/sjsu-data226/build_lab2: No such file or directory
[2024-11-10T23:45:40.159+0000] {subprocess.py:97} INFO - Command exited with return code 1
[2024-11-10T23:45:40.160+0000] {taskinstance.py:441} INFO - ::group::Post task execution logs
[2024-11-10T23:45:40.166+0000] {taskinstance.py:2905} ERROR - Task failed with exception
Traceback (most recent call last):
  File "/home/airflow/.local/lib/python3.12/site-packages/airflow/models/taskinstance.py", line 465, in _execute_task
    result = _execute_callable(context=context, **execute_callable_kwargs)
             ^^^^^^^^^^^^^^^^^^^^^^^^^^^^^^^^^^^^^^^^^^^^^^^^^^^^^^^^^^^^^
  File "/home/airflow/.local/lib/python3.12/site-packages/airflow/models/taskinstance.py", line 432, in _execute_callable
    return execute_callable(context=context, **execute_callable_kwargs)
           ^^^^^^^^^^^^^^^^^^^^^^^^^^^^^^^^^^^^^^^^^^^^^^^^^^^^^^^^^^^^
  File "/home/airflow/.local/lib/python3.12/site-packages/airflow/models/baseoperator.py", line 400, in wrapper
    return func(self, *args, **kwargs)
           ^^^^^^^^^^^^^^^^^^^^^^^^^^^
  File "/home/airflow/.local/lib/python3.12/site-packages/airflow/operators/bash.py", line 243, in execute
    raise AirflowException(
airflow.exceptions.AirflowException: Bash command failed. The command returned a non-zero exit code 1.
[2024-11-10T23:45:40.171+0000] {taskinstance.py:1206} INFO - Marking task as FAILED. dag_id=dbt_***_dag, task_id=dbt_run, run_id=manual__2024-11-10T23:45:37.775594+00:00, execution_date=20241110T234537, start_date=20241110T234540, end_date=20241110T234540
[2024-11-10T23:45:40.176+0000] {standard_task_runner.py:110} ERROR - Failed to execute job 167 for task dbt_run (Bash command failed. The command returned a non-zero exit code 1.; 2807)
[2024-11-10T23:45:40.188+0000] {local_task_job_runner.py:240} INFO - Task exited with return code 1
[2024-11-10T23:45:40.201+0000] {taskinstance.py:3498} INFO - 0 downstream tasks scheduled from follow-on schedule check
[2024-11-10T23:45:40.203+0000] {local_task_job_runner.py:222} INFO - ::endgroup::
